Workbook

Sheet Colony Data
A1: strain | B1: plate_group | C1: crop_path | D1: source_image | E1: equiv_diameter | F1: circularity | G1: solidity | H1: mean_hue | I1: mean_sat | J1: mean_val | K1: std_hue | L1: std_sat | M1: std_val | N1: texture_std
A2: ALE | B2: ALE_plate1 | C2: cropped_colonies\ALE\ALE(뒤)-1__colony01.jpg | D2: Colony picture (1)\Colony picture\ALE\ALE(뒤)-1.jpg | E2: 24.384 | F2: 0.864 | G2: 0.969 | H2: 45.909 | I2: 176.181 | J2: 55.419 | K2: 6.712 | L2: 56.404 | M2: 34.377 | N2: 33.714
A3: ALE | B3: ALE_plate1 | C3: cropped_colonies\ALE\ALE(뒤)-1__colony02.jpg | D3: Colony picture (1)\Colony picture\ALE\ALE(뒤)-1.jpg | E3: 16.313 | F3: 0.919 | G3: 0.986 | H3: 42.137 | I3: 177.597 | J3: 65.725 | K3: 1.853 | L3: 62.515 | M3: 33.112 | N3: 33.003
A4: ALE | B4: ALE_plate1 | C4: cropped_colonies\ALE\ALE(뒤)-1__colony03.jpg | D4: Colony picture (1)\Colony picture\ALE\ALE(뒤)-1.jpg | E4: 22.624 | F4: 0.876 | G4: 0.971 | H4: 42.158 | I4: 187.186 | J4: 59.658 | K4: 2.862 | L4: 59.774 | M4: 34.009 | N4: 33.541
A5: ALE | B5: ALE_plate1 | C5: cropped_colonies\ALE\ALE(뒤)-1__colony04.jpg | D5: Colony picture (1)\Colony picture\ALE\ALE(뒤)-1.jpg | E5: 43.167 | F5: 0.615 | G5: 0.884 | H5: 43.124 | I5: 199.187 | J5: 59.95 | K5: 5.288 | L5: 56.805 | M5: 36.757 | N5: 36.109
A6: ALE | B6: ALE_plate1 | C6: cropped_colonies\ALE\ALE(앞)-1__colony01.jpg | D6: Colony picture (1)\Colony picture\ALE\ALE(앞)-1.jpg | E6: 23.642 | F6: 0.889 | G6: 0.98 | H6: 59.008 | I6: 109.994 | J6: 53.392 | K6: 10.033 | L6: 22.229 | M6: 16.703 | N6: 16.444
A7: ALE | B7: ALE_plate1 | C7: cropped_colonies\ALE\ALE(앞)-1__colony02.jpg | D7: Colony picture (1)\Colony picture\ALE\ALE(앞)-1.jpg | E7: 15.181 | F7: 0.887 | G7: 0.968 | H7: 55.162 | I7: 93.083 | J7: 61.382 | K7: 6.636 | L7: 14.16 | M7: 13.224 | N7: 13.113
A8: ALE | B8: ALE_plate1 | C8: cropped_colonies\ALE\ALE(앞)-1__colony03.jpg | D8: Colony picture (1)\Colony picture\ALE\ALE(앞)-1.jpg | E8: 21.807 | F8: 0.872 | G8: 0.97 | H8: 57.776 | I8: 95.135 | J8: 59.786 | K8: 10.056 | L8: 13.754 | M8: 14.788 | N8: 14.58
A9: ALE | B9: ALE_plate1 | C9: cropped_colonies\ALE\ALE(앞)-1__colony04.jpg | D9: Colony picture (1)\Colony picture\ALE\ALE(앞)-1.jpg | E9: 42.483 | F9: 0.612 | G9: 0.886 | H9: 55.31 | I9: 103.991 | J9: 60.775 | K9: 10.532 | L9: 21.245 | M9: 19.5 | N9: 19.024
A10: ALE | B10: ALE_plate2 | C10: cropped_colonies\ALE\ALE(앞)-2__colony01.jpg | D10: Colony picture (1)\Colony picture\ALE\ALE(앞)-2.jpg | E10: 7.136 | F10: 0.838 | G10: 0.952 | H10: 56.865 | I10: 126.096 | J10: 43.596 | K10: 4.498 | L10: 47.433 | M10: 15.834 | N10: 15.902
A11: ALE | B11: ALE_plate2 | C11: cropped_colonies\ALE\ALE(앞)-2__colony02.jpg | D11: Colony picture (1)\Colony picture\ALE\ALE(앞)-2.jpg | E11: 10.249 | F11: 0.921 | G11: 0.988 | H11: 64.837 | I11: 125.469 | J11: 40.449 | K11: 7.243 | L11: 48.067 | M11: 14.865 | N11: 15.017
A12: ALE | B12: ALE_plate2 | C12: cropped_colonies\ALE\ALE(앞)-2__colony03.jpg | D12: Colony picture (1)\Colony picture\ALE\ALE(앞)-2.jpg | E12: 10.124 | F12: 0.898 | G12: 0.976 | H12: 61.031 | I12: 126.427 | J12: 43.729 | K12: 5.711 | L12: 54.672 | M12: 15.777 | N12: 16.035
A13: ALE | B13: ALE_plate2 | C13: cropped_colonies\ALE\ALE(앞)-2__colony04.jpg | D13: Colony picture (1)\Colony picture\ALE\ALE(앞)-2.jpg | E13: 9.772 | F13: 0.809 | G13: 0.938 | H13: 65.11 | I13: 130.165 | J13: 36.78 | K13: 6.019 | L13: 42.916 | M13: 12.628 | N13: 12.822
... A54: HS2 | B54: HS2_plate1 | C54: cropped_colonies\HS2\HS2(앞)-1__colony03.jpg | D54: Colony picture (1)\Colony picture\HS2\HS2(앞)-1.jpg | E54: 31.725 | F54: 0.893 | G54: 0.981 | H54: 67.875 | I54: 160.92 | J54: 32.424 | K54: 14.548 | L54: 54.952 | M54: 16.892 | N54: 16.109

Sheet Strain Summary
A1: strain | B1: feature | C1: n | D1: sum_x | E1: sum_x2 | F1: mean | G1: std
A2: HS2 | B2: equiv_diameter | C2: =SUMPRODUCT(('Colony Data'!$A$2:$A$54=$A2)*1) | D2: =SUMPRODUCT(('Colony Data'!$A$2:$A$54=$A2)*('Colony Data'!$E$2:$E$54)) | E2: =SUMPRODUCT(('Colony Data'!$A$2:$A$54=$A2)*('Colony Data'!$E$2:$E$54)^2) | F2: =IF(C2=0,"",D2/C2) | G2: =IF(C2<=1,"",SQRT((E2-(D2^2)/C2)/(C2-1)))
A3: HS2 | B3: circularity | C3: =SUMPRODUCT(('Colony Data'!$A$2:$A$54=$A3)*1) | D3: =SUMPRODUCT(('Colony Data'!$A$2:$A$54=$A3)*('Colony Data'!$F$2:$F$54)) | E3: =SUMPRODUCT(('Colony Data'!$A$2:$A$54=$A3)*('Colony Data'!$F$2:$F$54)^2) | F3: =IF(C3=0,"",D3/C3) | G3: =IF(C3<=1,"",SQRT((E3-(D3^2)/C3)/(C3-1)))
A4: HS2 | B4: solidity | C4: =SUMPRODUCT(('Colony Data'!$A$2:$A$54=$A4)*1) | D4: =SUMPRODUCT(('Colony Data'!$A$2:$A$54=$A4)*('Colony Data'!$G$2:$G$54)) | E4: =SUMPRODUCT(('Colony Data'!$A$2:$A$54=$A4)*('Colony Data'!$G$2:$G$54)^2) | F4: =IF(C4=0,"",D4/C4) | G4: =IF(C4<=1,"",SQRT((E4-(D4^2)/C4)/(C4-1)))
A5: HS2 | B5: mean_hue | C5: =SUMPRODUCT(('Colony Data'!$A$2:$A$54=$A5)*1) | D5: =SUMPRODUCT(('Colony Data'!$A$2:$A$54=$A5)*('Colony Data'!$H$2:$H$54)) | E5: =SUMPRODUCT(('Colony Data'!$A$2:$A$54=$A5)*('Colony Data'!$H$2:$H$54)^2) | F5: =IF(C5=0,"",D5/C5) | G5: =IF(C5<=1,"",SQRT((E5-(D5^2)/C5)/(C5-1)))
A6: HS2 | B6: mean_sat | C6: =SUMPRODUCT(('Colony Data'!$A$2:$A$54=$A6)*1) | D6: =SUMPRODUCT(('Colony Data'!$A$2:$A$54=$A6)*('Colony Data'!$I$2:$I$54)) | E6: =SUMPRODUCT(('Colony Data'!$A$2:$A$54=$A6)*('Colony Data'!$I$2:$I$54)^2) | F6: =IF(C6=0,"",D6/C6) | G6: =IF(C6<=1,"",SQRT((E6-(D6^2)/C6)/(C6-1)))
A7: HS2 | B7: mean_val | C7: =SUMPRODUCT(('Colony Data'!$A$2:$A$54=$A7)*1) | D7: =SUMPRODUCT(('Colony Data'!$A$2:$A$54=$A7)*('Colony Data'!$J$2:$J$54)) | E7: =SUMPRODUCT(('Colony Data'!$A$2:$A$54=$A7)*('Colony Data'!$J$2:$J$54)^2) | F7: =IF(C7=0,"",D7/C7) | G7: =IF(C7<=1,"",SQRT((E7-(D7^2)/C7)/(C7-1)))
A8: HS2 | B8: std_hue | C8: =SUMPRODUCT(('Colony Data'!$A$2:$A$54=$A8)*1) | D8: =SUMPRODUCT(('Colony Data'!$A$2:$A$54=$A8)*('Colony Data'!$K$2:$K$54)) | E8: =SUMPRODUCT(('Colony Data'!$A$2:$A$54=$A8)*('Colony Data'!$K$2:$K$54)^2) | F8: =IF(C8=0,"",D8/C8) | G8: =IF(C8<=1,"",SQRT((E8-(D8^2)/C8)/(C8-1)))
A9: HS2 | B9: std_sat | C9: =SUMPRODUCT(('Colony Data'!$A$2:$A$54=$A9)*1) | D9: =SUMPRODUCT(('Colony Data'!$A$2:$A$54=$A9)*('Colony Data'!$L$2:$L$54)) | E9: =SUMPRODUCT(('Colony Data'!$A$2:$A$54=$A9)*('Colony Data'!$L$2:$L$54)^2) | F9: =IF(C9=0,"",D9/C9) | G9: =IF(C9<=1,"",SQRT((E9-(D9^2)/C9)/(C9-1)))
A10: HS2 | B10: std_val | C10: =SUMPRODUCT(('Colony Data'!$A$2:$A$54=$A10)*1) | D10: =SUMPRODUCT(('Colony Data'!$A$2:$A$54=$A10)*('Colony Data'!$M$2:$M$54)) | E10: =SUMPRODUCT(('Colony Data'!$A$2:$A$54=$A10)*('Colony Data'!$M$2:$M$54)^2) | F10: =IF(C10=0,"",D10/C10) | G10: =IF(C10<=1,"",SQRT((E10-(D10^2)/C10)/(C10-1)))
A11: HS2 | B11: texture_std | C11: =SUMPRODUCT(('Colony Data'!$A$2:$A$54=$A11)*1) | D11: =SUMPRODUCT(('Colony Data'!$A$2:$A$54=$A11)*('Colony Data'!$N$2:$N$54)) | E11: =SUMPRODUCT(('Colony Data'!$A$2:$A$54=$A11)*('Colony Data'!$N$2:$N$54)^2) | F11: =IF(C11=0,"",D11/C11) | G11: =IF(C11<=1,"",SQRT((E11-(D11^2)/C11)/(C11-1)))
A12: ALE | B12: equiv_diameter | C12: =SUMPRODUCT(('Colony Data'!$A$2:$A$54=$A12)*1) | D12: =SUMPRODUCT(('Colony Data'!$A$2:$A$54=$A12)*('Colony Data'!$E$2:$E$54)) | E12: =SUMPRODUCT(('Colony Data'!$A$2:$A$54=$A12)*('Colony Data'!$E$2:$E$54)^2) | F12: =IF(C12=0,"",D12/C12) | G12: =IF(C12<=1,"",SQRT((E12-(D12^2)/C12)/(C12-1)))
A13: ALE | B13: circularity | C13: =SUMPRODUCT(('Colony Data'!$A$2:$A$54=$A13)*1) | D13: =SUMPRODUCT(('Colony Data'!$A$2:$A$54=$A13)*('Colony Data'!$F$2:$F$54)) | E13: =SUMPRODUCT(('Colony Data'!$A$2:$A$54=$A13)*('Colony Data'!$F$2:$F$54)^2) | F13: =IF(C13=0,"",D13/C13) | G13: =IF(C13<=1,"",SQRT((E13-(D13^2)/C13)/(C13-1)))
A14: ALE | B14: solidity | C14: =SUMPRODUCT(('Colony Data'!$A$2:$A$54=$A14)*1) | D14: =SUMPRODUCT(('Colony Data'!$A$2:$A$54=$A14)*('Colony Data'!$G$2:$G$54)) | E14: =SUMPRODUCT(('Colony Data'!$A$2:$A$54=$A14)*('Colony Data'!$G$2:$G$54)^2) | F14: =IF(C14=0,"",D14/C14) | G14: =IF(C14<=1,"",SQRT((E14-(D14^2)/C14)/(C14-1)))
A15: ALE | B15: mean_hue | C15: =SUMPRODUCT(('Colony Data'!$A$2:$A$54=$A15)*1) | D15: =SUMPRODUCT(('Colony Data'!$A$2:$A$54=$A15)*('Colony Data'!$H$2:$H$54)) | E15: =SUMPRODUCT(('Colony Data'!$A$2:$A$54=$A15)*('Colony Data'!$H$2:$H$54)^2) | F15: =IF(C15=0,"",D15/C15) | G15: =IF(C15<=1,"",SQRT((E15-(D15^2)/C15)/(C15-1)))
A16: ALE | B16: mean_sat | C16: =SUMPRODUCT(('Colony Data'!$A$2:$A$54=$A16)*1) | D16: =SUMPRODUCT(('Colony Data'!$A$2:$A$54=$A16)*('Colony Data'!$I$2:$I$54)) | E16: =SUMPRODUCT(('Colony Data'!$A$2:$A$54=$A16)*('Colony Data'!$I$2:$I$54)^2) | F16: =IF(C16=0,"",D16/C16) | G16: =IF(C16<=1,"",SQRT((E16-(D16^2)/C16)/(C16-1)))
A17: ALE | B17: mean_val | C17: =SUMPRODUCT(('Colony Data'!$A$2:$A$54=$A17)*1) | D17: =SUMPRODUCT(('Colony Data'!$A$2:$A$54=$A17)*('Colony Data'!$J$2:$J$54)) | E17: =SUMPRODUCT(('Colony Data'!$A$2:$A$54=$A17)*('Colony Data'!$J$2:$J$54)^2) | F17: =IF(C17=0,"",D17/C17) | G17: =IF(C17<=1,"",SQRT((E17-(D17^2)/C17)/(C17-1)))
A18: ALE | B18: std_hue | C18: =SUMPRODUCT(('Colony Data'!$A$2:$A$54=$A18)*1) | D18: =SUMPRODUCT(('Colony Data'!$A$2:$A$54=$A18)*('Colony Data'!$K$2:$K$54)) | E18: =SUMPRODUCT(('Colony Data'!$A$2:$A$54=$A18)*('Colony Data'!$K$2:$K$54)^2) | F18: =IF(C18=0,"",D18/C18) | G18: =IF(C18<=1,"",SQRT((E18-(D18^2)/C18)/(C18-1)))
A19: ALE | B19: std_sat | C19: =SUMPRODUCT(('Colony Data'!$A$2:$A$54=$A19)*1) | D19: =SUMPRODUCT(('Colony Data'!$A$2:$A$54=$A19)*('Colony Data'!$L$2:$L$54)) | E19: =SUMPRODUCT(('Colony Data'!$A$2:$A$54=$A19)*('Colony Data'!$L$2:$L$54)^2) | F19: =IF(C19=0,"",D19/C19) | G19: =IF(C19<=1,"",SQRT((E19-(D19^2)/C19)/(C19-1)))
A20: ALE | B20: std_val | C20: =SUMPRODUCT(('Colony Data'!$A$2:$A$54=$A20)*1) | D20: =SUMPRODUCT(('Colony Data'!$A$2:$A$54=$A20)*('Colony Data'!$M$2:$M$54)) | E20: =SUMPRODUCT(('Colony Data'!$A$2:$A$54=$A20)*('Colony Data'!$M$2:$M$54)^2) | F20: =IF(C20=0,"",D20/C20) | G20: =IF(C20<=1,"",SQRT((E20-(D20^2)/C20)/(C20-1)))
A21: ALE | B21: texture_std | C21: =SUMPRODUCT(('Colony Data'!$A$2:$A$54=$A21)*1) | D21: =SUMPRODUCT(('Colony Data'!$A$2:$A$54=$A21)*('Colony Data'!$N$2:$N$54)) | E21: =SUMPRODUCT(('Colony Data'!$A$2:$A$54=$A21)*('Colony Data'!$N$2:$N$54)^2) | F21: =IF(C21=0,"",D21/C21) | G21: =IF(C21<=1,"",SQRT((E21-(D21^2)/C21)/(C21-1)))
A22: HMF | B22: equiv_diameter | C22: =SUMPRODUCT(('Colony Data'!$A$2:$A$54=$A22)*1) | D22: =SUMPRODUCT(('Colony Data'!$A$2:$A$54=$A22)*('Colony Data'!$E$2:$E$54)) | E22: =SUMPRODUCT(('Colony Data'!$A$2:$A$54=$A22)*('Colony Data'!$E$2:$E$54)^2) | F22: =IF(C22=0,"",D22/C22) | G22: =IF(C22<=1,"",SQRT((E22-(D22^2)/C22)/(C22-1)))
A23: HMF | B23: circularity | C23: =SUMPRODUCT(('Colony Data'!$A$2:$A$54=$A23)*1) | D23: =SUMPRODUCT(('Colony Data'!$A$2:$A$54=$A23)*('Colony Data'!$F$2:$F$54)) | E23: =SUMPRODUCT(('Colony Data'!$A$2:$A$54=$A23)*('Colony Data'!$F$2:$F$54)^2) | F23: =IF(C23=0,"",D23/C23) | G23: =IF(C23<=1,"",SQRT((E23-(D23^2)/C23)/(C23-1)))
A24: HMF | B24: solidity | C24: =SUMPRODUCT(('Colony Data'!$A$2:$A$54=$A24)*1) | D24: =SUMPRODUCT(('Colony Data'!$A$2:$A$54=$A24)*('Colony Data'!$G$2:$G$54)) | E24: =SUMPRODUCT(('Colony Data'!$A$2:$A$54=$A24)*('Colony Data'!$G$2:$G$54)^2) | F24: =IF(C24=0,"",D24/C24) | G24: =IF(C24<=1,"",SQRT((E24-(D24^2)/C24)/(C24-1)))
A25: HMF | B25: mean_hue | C25: =SUMPRODUCT(('Colony Data'!$A$2:$A$54=$A25)*1) | D25: =SUMPRODUCT(('Colony Data'!$A$2:$A$54=$A25)*('Colony Data'!$H$2:$H$54)) | E25: =SUMPRODUCT(('Colony Data'!$A$2:$A$54=$A25)*('Colony Data'!$H$2:$H$54)^2) | F25: =IF(C25=0,"",D25/C25) | G25: =IF(C25<=1,"",SQRT((E25-(D25^2)/C25)/(C25-1)))
A26: HMF | B26: mean_sat | C26: =SUMPRODUCT(('Colony Data'!$A$2:$A$54=$A26)*1) | D26: =SUMPRODUCT(('Colony Data'!$A$2:$A$54=$A26)*('Colony Data'!$I$2:$I$54)) | E26: =SUMPRODUCT(('Colony Data'!$A$2:$A$54=$A26)*('Colony Data'!$I$2:$I$54)^2) | F26: =IF(C26=0,"",D26/C26) | G26: =IF(C26<=1,"",SQRT((E26-(D26^2)/C26)/(C26-1)))
A27: HMF | B27: mean_val | C27: =SUMPRODUCT(('Colony Data'!$A$2:$A$54=$A27)*1) | D27: =SUMPRODUCT(('Colony Data'!$A$2:$A$54=$A27)*('Colony Data'!$J$2:$J$54)) | E27: =SUMPRODUCT(('Colony Data'!$A$2:$A$54=$A27)*('Colony Data'!$J$2:$J$54)^2) | F27: =IF(C27=0,"",D27/C27) | G27: =IF(C27<=1,"",SQRT((E27-(D27^2)/C27)/(C27-1)))
A28: HMF | B28: std_hue | C28: =SUMPRODUCT(('Colony Data'!$A$2:$A$54=$A28)*1) | D28: =SUMPRODUCT(('Colony Data'!$A$2:$A$54=$A28)*('Colony Data'!$K$2:$K$54)) | E28: =SUMPRODUCT(('Colony Data'!$A$2:$A$54=$A28)*('Colony Data'!$K$2:$K$54)^2) | F28: =IF(C28=0,"",D28/C28) | G28: =IF(C28<=1,"",SQRT((E28-(D28^2)/C28)/(C28-1)))
A29: HMF | B29: std_sat | C29: =SUMPRODUCT(('Colony Data'!$A$2:$A$54=$A29)*1) | D29: =SUMPRODUCT(('Colony Data'!$A$2:$A$54=$A29)*('Colony Data'!$L$2:$L$54)) | E29: =SUMPRODUCT(('Colony Data'!$A$2:$A$54=$A29)*('Colony Data'!$L$2:$L$54)^2) | F29: =IF(C29=0,"",D29/C29) | G29: =IF(C29<=1,"",SQRT((E29-(D29^2)/C29)/(C29-1)))
A30: HMF | B30: std_val | C30: =SUMPRODUCT(('Colony Data'!$A$2:$A$54=$A30)*1) | D30: =SUMPRODUCT(('Colony Data'!$A$2:$A$54=$A30)*('Colony Data'!$M$2:$M$54)) | E30: =SUMPRODUCT(('Colony Data'!$A$2:$A$54=$A30)*('Colony Data'!$M$2:$M$54)^2) | F30: =IF(C30=0,"",D30/C30) | G30: =IF(C30<=1,"",SQRT((E30-(D30^2)/C30)/(C30-1)))
A31: HMF | B31: texture_std | C31: =SUMPRODUCT(('Colony Data'!$A$2:$A$54=$A31)*1) | D31: =SUMPRODUCT(('Colony Data'!$A$2:$A$54=$A31)*('Colony Data'!$N$2:$N$54)) | E31: =SUMPRODUCT(('Colony Data'!$A$2:$A$54=$A31)*('Colony Data'!$N$2:$N$54)^2) | F31: =IF(C31=0,"",D31/C31) | G31: =IF(C31<=1,"",SQRT((E31-(D31^2)/C31)/(C31-1)))
A32: HS19 | B32: equiv_diameter | C32: =SUMPRODUCT(('Colony Data'!$A$2:$A$54=$A32)*1) | D32: =SUMPRODUCT(('Colony Data'!$A$2:$A$54=$A32)*('Colony Data'!$E$2:$E$54)) | E32: =SUMPRODUCT(('Colony Data'!$A$2:$A$54=$A32)*('Colony Data'!$E$2:$E$54)^2) | F32: =IF(C32=0,"",D32/C32) | G32: =IF(C32<=1,"",SQRT((E32-(D32^2)/C32)/(C32-1)))
A33: HS19 | B33: circularity | C33: =SUMPRODUCT(('Colony Data'!$A$2:$A$54=$A33)*1) | D33: =SUMPRODUCT(('Colony Data'!$A$2:$A$54=$A33)*('Colony Data'!$F$2:$F$54)) | E33: =SUMPRODUCT(('Colony Data'!$A$2:$A$54=$A33)*('Colony Data'!$F$2:$F$54)^2) | F33: =IF(C33=0,"",D33/C33) | G33: =IF(C33<=1,"",SQRT((E33-(D33^2)/C33)/(C33-1)))
A34: HS19 | B34: solidity | C34: =SUMPRODUCT(('Colony Data'!$A$2:$A$54=$A34)*1) | D34: =SUMPRODUCT(('Colony Data'!$A$2:$A$54=$A34)*('Colony Data'!$G$2:$G$54)) | E34: =SUMPRODUCT(('Colony Data'!$A$2:$A$54=$A34)*('Colony Data'!$G$2:$G$54)^2) | F34: =IF(C34=0,"",D34/C34) | G34: =IF(C34<=1,"",SQRT((E34-(D34^2)/C34)/(C34-1)))
A35: HS19 | B35: mean_hue | C35: =SUMPRODUCT(('Colony Data'!$A$2:$A$54=$A35)*1) | D35: =SUMPRODUCT(('Colony Data'!$A$2:$A$54=$A35)*('Colony Data'!$H$2:$H$54)) | E35: =SUMPRODUCT(('Colony Data'!$A$2:$A$54=$A35)*('Colony Data'!$H$2:$H$54)^2) | F35: =IF(C35=0,"",D35/C35) | G35: =IF(C35<=1,"",SQRT((E35-(D35^2)/C35)/(C35-1)))
A36: HS19 | B36: mean_sat | C36: =SUMPRODUCT(('Colony Data'!$A$2:$A$54=$A36)*1) | D36: =SUMPRODUCT(('Colony Data'!$A$2:$A$54=$A36)*('Colony Data'!$I$2:$I$54)) | E36: =SUMPRODUCT(('Colony Data'!$A$2:$A$54=$A36)*('Colony Data'!$I$2:$I$54)^2) | F36: =IF(C36=0,"",D36/C36) | G36: =IF(C36<=1,"",SQRT((E36-(D36^2)/C36)/(C36-1)))
A37: HS19 | B37: mean_val | C37: =SUMPRODUCT(('Colony Data'!$A$2:$A$54=$A37)*1) | D37: =SUMPRODUCT(('Colony Data'!$A$2:$A$54=$A37)*('Colony Data'!$J$2:$J$54)) | E37: =SUMPRODUCT(('Colony Data'!$A$2:$A$54=$A37)*('Colony Data'!$J$2:$J$54)^2) | F37: =IF(C37=0,"",D37/C37) | G37: =IF(C37<=1,"",SQRT((E37-(D37^2)/C37)/(C37-1)))
A38: HS19 | B38: std_hue | C38: =SUMPRODUCT(('Colony Data'!$A$2:$A$54=$A38)*1) | D38: =SUMPRODUCT(('Colony Data'!$A$2:$A$54=$A38)*('Colony Data'!$K$2:$K$54)) | E38: =SUMPRODUCT(('Colony Data'!$A$2:$A$54=$A38)*('Colony Data'!$K$2:$K$54)^2) | F38: =IF(C38=0,"",D38/C38) | G38: =IF(C38<=1,"",SQRT((E38-(D38^2)/C38)/(C38-1)))
A39: HS19 | B39: std_sat | C39: =SUMPRODUCT(('Colony Data'!$A$2:$A$54=$A39)*1) | D39: =SUMPRODUCT(('Colony Data'!$A$2:$A$54=$A39)*('Colony Data'!$L$2:$L$54)) | E39: =SUMPRODUCT(('Colony Data'!$A$2:$A$54=$A39)*('Colony Data'!$L$2:$L$54)^2) | F39: =IF(C39=0,"",D39/C39) | G39: =IF(C39<=1,"",SQRT((E39-(D39^2)/C39)/(C39-1)))
A40: HS19 | B40: std_val | C40: =SUMPRODUCT(('Colony Data'!$A$2:$A$54=$A40)*1) | D40: =SUMPRODUCT(('Colony Data'!$A$2:$A$54=$A40)*('Colony Data'!$M$2:$M$54)) | E40: =SUMPRODUCT(('Colony Data'!$A$2:$A$54=$A40)*('Colony Data'!$M$2:$M$54)^2) | F40: =IF(C40=0,"",D40/C40) | G40: =IF(C40<=1,"",SQRT((E40-(D40^2)/C40)/(C40-1)))
...

Sheet Plate Summary
A1: plate_group | B1: strain | C1: feature | D1: n | E1: sum_x | F1: sum_x2 | G1: mean | H1: std
A2: ALE_plate1 | B2: ALE | C2: equiv_diameter | D2: =SUMPRODUCT(('Colony Data'!$B$2:$B$54=$A2)*1) | E2: =SUMPRODUCT(('Colony Data'!$B$2:$B$54=$A2)*('Colony Data'!$E$2:$E$54)) | F2: =SUMPRODUCT(('Colony Data'!$B$2:$B$54=$A2)*('Colony Data'!$E$2:$E$54)^2) | G2: =IF(D2=0,"",E2/D2) | H2: =IF(D2<=1,"",SQRT((F2-(E2^2)/D2)/(D2-1)))
A3: ALE_plate1 | B3: ALE | C3: circularity | D3: =SUMPRODUCT(('Colony Data'!$B$2:$B$54=$A3)*1) | E3: =SUMPRODUCT(('Colony Data'!$B$2:$B$54=$A3)*('Colony Data'!$F$2:$F$54)) | F3: =SUMPRODUCT(('Colony Data'!$B$2:$B$54=$A3)*('Colony Data'!$F$2:$F$54)^2) | G3: =IF(D3=0,"",E3/D3) | H3: =IF(D3<=1,"",SQRT((F3-(E3^2)/D3)/(D3-1)))
A4: ALE_plate1 | B4: ALE | C4: solidity | D4: =SUMPRODUCT(('Colony Data'!$B$2:$B$54=$A4)*1) | E4: =SUMPRODUCT(('Colony Data'!$B$2:$B$54=$A4)*('Colony Data'!$G$2:$G$54)) | F4: =SUMPRODUCT(('Colony Data'!$B$2:$B$54=$A4)*('Colony Data'!$G$2:$G$54)^2) | G4: =IF(D4=0,"",E4/D4) | H4: =IF(D4<=1,"",SQRT((F4-(E4^2)/D4)/(D4-1)))
A5: ALE_plate1 | B5: ALE | C5: mean_hue | D5: =SUMPRODUCT(('Colony Data'!$B$2:$B$54=$A5)*1) | E5: =SUMPRODUCT(('Colony Data'!$B$2:$B$54=$A5)*('Colony Data'!$H$2:$H$54)) | F5: =SUMPRODUCT(('Colony Data'!$B$2:$B$54=$A5)*('Colony Data'!$H$2:$H$54)^2) | G5: =IF(D5=0,"",E5/D5) | H5: =IF(D5<=1,"",SQRT((F5-(E5^2)/D5)/(D5-1)))
A6: ALE_plate1 | B6: ALE | C6: mean_sat | D6: =SUMPRODUCT(('Colony Data'!$B$2:$B$54=$A6)*1) | E6: =SUMPRODUCT(('Colony Data'!$B$2:$B$54=$A6)*('Colony Data'!$I$2:$I$54)) | F6: =SUMPRODUCT(('Colony Data'!$B$2:$B$54=$A6)*('Colony Data'!$I$2:$I$54)^2) | G6: =IF(D6=0,"",E6/D6) | H6: =IF(D6<=1,"",SQRT((F6-(E6^2)/D6)/(D6-1)))
A7: ALE_plate1 | B7: ALE | C7: mean_val | D7: =SUMPRODUCT(('Colony Data'!$B$2:$B$54=$A7)*1) | E7: =SUMPRODUCT(('Colony Data'!$B$2:$B$54=$A7)*('Colony Data'!$J$2:$J$54)) | F7: =SUMPRODUCT(('Colony Data'!$B$2:$B$54=$A7)*('Colony Data'!$J$2:$J$54)^2) | G7: =IF(D7=0,"",E7/D7) | H7: =IF(D7<=1,"",SQRT((F7-(E7^2)/D7)/(D7-1)))
A8: ALE_plate1 | B8: ALE | C8: std_hue | D8: =SUMPRODUCT(('Colony Data'!$B$2:$B$54=$A8)*1) | E8: =SUMPRODUCT(('Colony Data'!$B$2:$B$54=$A8)*('Colony Data'!$K$2:$K$54)) | F8: =SUMPRODUCT(('Colony Data'!$B$2:$B$54=$A8)*('Colony Data'!$K$2:$K$54)^2) | G8: =IF(D8=0,"",E8/D8) | H8: =IF(D8<=1,"",SQRT((F8-(E8^2)/D8)/(D8-1)))
A9: ALE_plate1 | B9: ALE | C9: std_sat | D9: =SUMPRODUCT(('Colony Data'!$B$2:$B$54=$A9)*1) | E9: =SUMPRODUCT(('Colony Data'!$B$2:$B$54=$A9)*('Colony Data'!$L$2:$L$54)) | F9: =SUMPRODUCT(('Colony Data'!$B$2:$B$54=$A9)*('Colony Data'!$L$2:$L$54)^2) | G9: =IF(D9=0,"",E9/D9) | H9: =IF(D9<=1,"",SQRT((F9-(E9^2)/D9)/(D9-1)))
A10: ALE_plate1 | B10: ALE | C10: std_val | D10: =SUMPRODUCT(('Colony Data'!$B$2:$B$54=$A10)*1) | E10: =SUMPRODUCT(('Colony Data'!$B$2:$B$54=$A10)*('Colony Data'!$M$2:$M$54)) | F10: =SUMPRODUCT(('Colony Data'!$B$2:$B$54=$A10)*('Colony Data'!$M$2:$M$54)^2) | G10: =IF(D10=0,"",E10/D10) | H10: =IF(D10<=1,"",SQRT((F10-(E10^2)/D10)/(D10-1)))
A11: ALE_plate1 | B11: ALE | C11: texture_std | D11: =SUMPRODUCT(('Colony Data'!$B$2:$B$54=$A11)*1) | E11: =SUMPRODUCT(('Colony Data'!$B$2:$B$54=$A11)*('Colony Data'!$N$2:$N$54)) | F11: =SUMPRODUCT(('Colony Data'!$B$2:$B$54=$A11)*('Colony Data'!$N$2:$N$54)^2) | G11: =IF(D11=0,"",E11/D11) | H11: =IF(D11<=1,"",SQRT((F11-(E11^2)/D11)/(D11-1)))
A12: ALE_plate2 | B12: ALE | C12: equiv_diameter | D12: =SUMPRODUCT(('Colony Data'!$B$2:$B$54=$A12)*1) | E12: =SUMPRODUCT(('Colony Data'!$B$2:$B$54=$A12)*('Colony Data'!$E$2:$E$54)) | F12: =SUMPRODUCT(('Colony Data'!$B$2:$B$54=$A12)*('Colony Data'!$E$2:$E$54)^2) | G12: =IF(D12=0,"",E12/D12) | H12: =IF(D12<=1,"",SQRT((F12-(E12^2)/D12)/(D12-1)))
A13: ALE_plate2 | B13: ALE | C13: circularity | D13: =SUMPRODUCT(('Colony Data'!$B$2:$B$54=$A13)*1) | E13: =SUMPRODUCT(('Colony Data'!$B$2:$B$54=$A13)*('Colony Data'!$F$2:$F$54)) | F13: =SUMPRODUCT(('Colony Data'!$B$2:$B$54=$A13)*('Colony Data'!$F$2:$F$54)^2) | G13: =IF(D13=0,"",E13/D13) | H13: =IF(D13<=1,"",SQRT((F13-(E13^2)/D13)/(D13-1)))
A14: ALE_plate2 | B14: ALE | C14: solidity | D14: =SUMPRODUCT(('Colony Data'!$B$2:$B$54=$A14)*1) | E14: =SUMPRODUCT(('Colony Data'!$B$2:$B$54=$A14)*('Colony Data'!$G$2:$G$54)) | F14: =SUMPRODUCT(('Colony Data'!$B$2:$B$54=$A14)*('Colony Data'!$G$2:$G$54)^2) | G14: =IF(D14=0,"",E14/D14) | H14: =IF(D14<=1,"",SQRT((F14-(E14^2)/D14)/(D14-1)))
A15: ALE_plate2 | B15: ALE | C15: mean_hue | D15: =SUMPRODUCT(('Colony Data'!$B$2:$B$54=$A15)*1) | E15: =SUMPRODUCT(('Colony Data'!$B$2:$B$54=$A15)*('Colony Data'!$H$2:$H$54)) | F15: =SUMPRODUCT(('Colony Data'!$B$2:$B$54=$A15)*('Colony Data'!$H$2:$H$54)^2) | G15: =IF(D15=0,"",E15/D15) | H15: =IF(D15<=1,"",SQRT((F15-(E15^2)/D15)/(D15-1)))
A16: ALE_plate2 | B16: ALE | C16: mean_sat | D16: =SUMPRODUCT(('Colony Data'!$B$2:$B$54=$A16)*1) | E16: =SUMPRODUCT(('Colony Data'!$B$2:$B$54=$A16)*('Colony Data'!$I$2:$I$54)) | F16: =SUMPRODUCT(('Colony Data'!$B$2:$B$54=$A16)*('Colony Data'!$I$2:$I$54)^2) | G16: =IF(D16=0,"",E16/D16) | H16: =IF(D16<=1,"",SQRT((F16-(E16^2)/D16)/(D16-1)))
A17: ALE_plate2 | B17: ALE | C17: mean_val | D17: =SUMPRODUCT(('Colony Data'!$B$2:$B$54=$A17)*1) | E17: =SUMPRODUCT(('Colony Data'!$B$2:$B$54=$A17)*('Colony Data'!$J$2:$J$54)) | F17: =SUMPRODUCT(('Colony Data'!$B$2:$B$54=$A17)*('Colony Data'!$J$2:$J$54)^2) | G17: =IF(D17=0,"",E17/D17) | H17: =IF(D17<=1,"",SQRT((F17-(E17^2)/D17)/(D17-1)))
A18: ALE_plate2 | B18: ALE | C18: std_hue | D18: =SUMPRODUCT(('Colony Data'!$B$2:$B$54=$A18)*1) | E18: =SUMPRODUCT(('Colony Data'!$B$2:$B$54=$A18)*('Colony Data'!$K$2:$K$54)) | F18: =SUMPRODUCT(('Colony Data'!$B$2:$B$54=$A18)*('Colony Data'!$K$2:$K$54)^2) | G18: =IF(D18=0,"",E18/D18) | H18: =IF(D18<=1,"",SQRT((F18-(E18^2)/D18)/(D18-1)))
A19: ALE_plate2 | B19: ALE | C19: std_sat | D19: =SUMPRODUCT(('Colony Data'!$B$2:$B$54=$A19)*1) | E19: =SUMPRODUCT(('Colony Data'!$B$2:$B$54=$A19)*('Colony Data'!$L$2:$L$54)) | F19: =SUMPRODUCT(('Colony Data'!$B$2:$B$54=$A19)*('Colony Data'!$L$2:$L$54)^2) | G19: =IF(D19=0,"",E19/D19) | H19: =IF(D19<=1,"",SQRT((F19-(E19^2)/D19)/(D19-1)))
A20: ALE_plate2 | B20: ALE | C20: std_val | D20: =SUMPRODUCT(('Colony Data'!$B$2:$B$54=$A20)*1) | E20: =SUMPRODUCT(('Colony Data'!$B$2:$B$54=$A20)*('Colony Data'!$M$2:$M$54)) | F20: =SUMPRODUCT(('Colony Data'!$B$2:$B$54=$A20)*('Colony Data'!$M$2:$M$54)^2) | G20: =IF(D20=0,"",E20/D20) | H20: =IF(D20<=1,"",SQRT((F20-(E20^2)/D20)/(D20-1)))
A21: ALE_plate2 | B21: ALE | C21: texture_std | D21: =SUMPRODUCT(('Colony Data'!$B$2:$B$54=$A21)*1) | E21: =SUMPRODUCT(('Colony Data'!$B$2:$B$54=$A21)*('Colony Data'!$N$2:$N$54)) | F21: =SUMPRODUCT(('Colony Data'!$B$2:$B$54=$A21)*('Colony Data'!$N$2:$N$54)^2) | G21: =IF(D21=0,"",E21/D21) | H21: =IF(D21<=1,"",SQRT((F21-(E21^2)/D21)/(D21-1)))
A22: ALE_plate3 | B22: ALE | C22: equiv_diameter | D22: =SUMPRODUCT(('Colony Data'!$B$2:$B$54=$A22)*1) | E22: =SUMPRODUCT(('Colony Data'!$B$2:$B$54=$A22)*('Colony Data'!$E$2:$E$54)) | F22: =SUMPRODUCT(('Colony Data'!$B$2:$B$54=$A22)*('Colony Data'!$E$2:$E$54)^2) | G22: =IF(D22=0,"",E22/D22) | H22: =IF(D22<=1,"",SQRT((F22-(E22^2)/D22)/(D22-1)))
A23: ALE_plate3 | B23: ALE | C23: circularity | D23: =SUMPRODUCT(('Colony Data'!$B$2:$B$54=$A23)*1) | E23: =SUMPRODUCT(('Colony Data'!$B$2:$B$54=$A23)*('Colony Data'!$F$2:$F$54)) | F23: =SUMPRODUCT(('Colony Data'!$B$2:$B$54=$A23)*('Colony Data'!$F$2:$F$54)^2) | G23: =IF(D23=0,"",E23/D23) | H23: =IF(D23<=1,"",SQRT((F23-(E23^2)/D23)/(D23-1)))
A24: ALE_plate3 | B24: ALE | C24: solidity | D24: =SUMPRODUCT(('Colony Data'!$B$2:$B$54=$A24)*1) | E24: =SUMPRODUCT(('Colony Data'!$B$2:$B$54=$A24)*('Colony Data'!$G$2:$G$54)) | F24: =SUMPRODUCT(('Colony Data'!$B$2:$B$54=$A24)*('Colony Data'!$G$2:$G$54)^2) | G24: =IF(D24=0,"",E24/D24) | H24: =IF(D24<=1,"",SQRT((F24-(E24^2)/D24)/(D24-1)))
A25: ALE_plate3 | B25: ALE | C25: mean_hue | D25: =SUMPRODUCT(('Colony Data'!$B$2:$B$54=$A25)*1) | E25: =SUMPRODUCT(('Colony Data'!$B$2:$B$54=$A25)*('Colony Data'!$H$2:$H$54)) | F25: =SUMPRODUCT(('Colony Data'!$B$2:$B$54=$A25)*('Colony Data'!$H$2:$H$54)^2) | G25: =IF(D25=0,"",E25/D25) | H25: =IF(D25<=1,"",SQRT((F25-(E25^2)/D25)/(D25-1)))
A26: ALE_plate3 | B26: ALE | C26: mean_sat | D26: =SUMPRODUCT(('Colony Data'!$B$2:$B$54=$A26)*1) | E26: =SUMPRODUCT(('Colony Data'!$B$2:$B$54=$A26)*('Colony Data'!$I$2:$I$54)) | F26: =SUMPRODUCT(('Colony Data'!$B$2:$B$54=$A26)*('Colony Data'!$I$2:$I$54)^2) | G26: =IF(D26=0,"",E26/D26) | H26: =IF(D26<=1,"",SQRT((F26-(E26^2)/D26)/(D26-1)))
A27: ALE_plate3 | B27: ALE | C27: mean_val | D27: =SUMPRODUCT(('Colony Data'!$B$2:$B$54=$A27)*1) | E27: =SUMPRODUCT(('Colony Data'!$B$2:$B$54=$A27)*('Colony Data'!$J$2:$J$54)) | F27: =SUMPRODUCT(('Colony Data'!$B$2:$B$54=$A27)*('Colony Data'!$J$2:$J$54)^2) | G27: =IF(D27=0,"",E27/D27) | H27: =IF(D27<=1,"",SQRT((F27-(E27^2)/D27)/(D27-1)))
A28: ALE_plate3 | B28: ALE | C28: std_hue | D28: =SUMPRODUCT(('Colony Data'!$B$2:$B$54=$A28)*1) | E28: =SUMPRODUCT(('Colony Data'!$B$2:$B$54=$A28)*('Colony Data'!$K$2:$K$54)) | F28: =SUMPRODUCT(('Colony Data'!$B$2:$B$54=$A28)*('Colony Data'!$K$2:$K$54)^2) | G28: =IF(D28=0,"",E28/D28) | H28: =IF(D28<=1,"",SQRT((F28-(E28^2)/D28)/(D28-1)))
A29: ALE_plate3 | B29: ALE | C29: std_sat | D29: =SUMPRODUCT(('Colony Data'!$B$2:$B$54=$A29)*1) | E29: =SUMPRODUCT(('Colony Data'!$B$2:$B$54=$A29)*('Colony Data'!$L$2:$L$54)) | F29: =SUMPRODUCT(('Colony Data'!$B$2:$B$54=$A29)*('Colony Data'!$L$2:$L$54)^2) | G29: =IF(D29=0,"",E29/D29) | H29: =IF(D29<=1,"",SQRT((F29-(E29^2)/D29)/(D29-1)))
A30: ALE_plate3 | B30: ALE | C30: std_val | D30: =SUMPRODUCT(('Colony Data'!$B$2:$B$54=$A30)*1) | E30: =SUMPRODUCT(('Colony Data'!$B$2:$B$54=$A30)*('Colony Data'!$M$2:$M$54)) | F30: =SUMPRODUCT(('Colony Data'!$B$2:$B$54=$A30)*('Colony Data'!$M$2:$M$54)^2) | G30: =IF(D30=0,"",E30/D30) | H30: =IF(D30<=1,"",SQRT((F30-(E30^2)/D30)/(D30-1)))
A31: ALE_plate3 | B31: ALE | C31: texture_std | D31: =SUMPRODUCT(('Colony Data'!$B$2:$B$54=$A31)*1) | E31: =SUMPRODUCT(('Colony Data'!$B$2:$B$54=$A31)*('Colony Data'!$N$2:$N$54)) | F31: =SUMPRODUCT(('Colony Data'!$B$2:$B$54=$A31)*('Colony Data'!$N$2:$N$54)^2) | G31: =IF(D31=0,"",E31/D31) | H31: =IF(D31<=1,"",SQRT((F31-(E31^2)/D31)/(D31-1)))
A32: HMF_plate1 | B32: HMF | C32: equiv_diameter | D32: =SUMPRODUCT(('Colony Data'!$B$2:$B$54=$A32)*1) | E32: =SUMPRODUCT(('Colony Data'!$B$2:$B$54=$A32)*('Colony Data'!$E$2:$E$54)) | F32: =SUMPRODUCT(('Colony Data'!$B$2:$B$54=$A32)*('Colony Data'!$E$2:$E$54)^2) | G32: =IF(D32=0,"",E32/D32) | H32: =IF(D32<=1,"",SQRT((F32-(E32^2)/D32)/(D32-1)))
A33: HMF_plate1 | B33: HMF | C33: circularity | D33: =SUMPRODUCT(('Colony Data'!$B$2:$B$54=$A33)*1) | E33: =SUMPRODUCT(('Colony Data'!$B$2:$B$54=$A33)*('Colony Data'!$F$2:$F$54)) | F33: =SUMPRODUCT(('Colony Data'!$B$2:$B$54=$A33)*('Colony Data'!$F$2:$F$54)^2) | G33: =IF(D33=0,"",E33/D33) | H33: =IF(D33<=1,"",SQRT((F33-(E33^2)/D33)/(D33-1)))
A34: HMF_plate1 | B34: HMF | C34: solidity | D34: =SUMPRODUCT(('Colony Data'!$B$2:$B$54=$A34)*1) | E34: =SUMPRODUCT(('Colony Data'!$B$2:$B$54=$A34)*('Colony Data'!$G$2:$G$54)) | F34: =SUMPRODUCT(('Colony Data'!$B$2:$B$54=$A34)*('Colony Data'!$G$2:$G$54)^2) | G34: =IF(D34=0,"",E34/D34) | H34: =IF(D34<=1,"",SQRT((F34-(E34^2)/D34)/(D34-1)))
A35: HMF_plate1 | B35: HMF | C35: mean_hue | D35: =SUMPRODUCT(('Colony Data'!$B$2:$B$54=$A35)*1) | E35: =SUMPRODUCT(('Colony Data'!$B$2:$B$54=$A35)*('Colony Data'!$H$2:$H$54)) | F35: =SUMPRODUCT(('Colony Data'!$B$2:$B$54=$A35)*('Colony Data'!$H$2:$H$54)^2) | G35: =IF(D35=0,"",E35/D35) | H35: =IF(D35<=1,"",SQRT((F35-(E35^2)/D35)/(D35-1)))
A36: HMF_plate1 | B36: HMF | C36: mean_sat | D36: =SUMPRODUCT(('Colony Data'!$B$2:$B$54=$A36)*1) | E36: =SUMPRODUCT(('Colony Data'!$B$2:$B$54=$A36)*('Colony Data'!$I$2:$I$54)) | F36: =SUMPRODUCT(('Colony Data'!$B$2:$B$54=$A36)*('Colony Data'!$I$2:$I$54)^2) | G36: =IF(D36=0,"",E36/D36) | H36: =IF(D36<=1,"",SQRT((F36-(E36^2)/D36)/(D36-1)))
A37: HMF_plate1 | B37: HMF | C37: mean_val | D37: =SUMPRODUCT(('Colony Data'!$B$2:$B$54=$A37)*1) | E37: =SUMPRODUCT(('Colony Data'!$B$2:$B$54=$A37)*('Colony Data'!$J$2:$J$54)) | F37: =SUMPRODUCT(('Colony Data'!$B$2:$B$54=$A37)*('Colony Data'!$J$2:$J$54)^2) | G37: =IF(D37=0,"",E37/D37) | H37: =IF(D37<=1,"",SQRT((F37-(E37^2)/D37)/(D37-1)))
A38: HMF_plate1 | B38: HMF | C38: std_hue | D38: =SUMPRODUCT(('Colony Data'!$B$2:$B$54=$A38)*1) | E38: =SUMPRODUCT(('Colony Data'!$B$2:$B$54=$A38)*('Colony Data'!$K$2:$K$54)) | F38: =SUMPRODUCT(('Colony Data'!$B$2:$B$54=$A38)*('Colony Data'!$K$2:$K$54)^2) | G38: =IF(D38=0,"",E38/D38) | H38: =IF(D38<=1,"",SQRT((F38-(E38^2)/D38)/(D38-1)))
A39: HMF_plate1 | B39: HMF | C39: std_sat | D39: =SUMPRODUCT(('Colony Data'!$B$2:$B$54=$A39)*1) | E39: =SUMPRODUCT(('Colony Data'!$B$2:$B$54=$A39)*('Colony Data'!$L$2:$L$54)) | F39: =SUMPRODUCT(('Colony Data'!$B$2:$B$54=$A39)*('Colony Data'!$L$2:$L$54)^2) | G39: =IF(D39=0,"",E39/D39) | H39: =IF(D39<=1,"",SQRT((F39-(E39^2)/D39)/(D39-1)))
A40: HMF_plate1 | B40: HMF | C40: std_val | D40: =SUMPRODUCT(('Colony Data'!$B$2:$B$54=$A40)*1) | E40: =SUMPRODUCT(('Colony Data'!$B$2:$B$54=$A40)*('Colony Data'!$M$2:$M$54)) | F40: =SUMPRODUCT(('Colony Data'!$B$2:$B$54=$A40)*('Colony Data'!$M$2:$M$54)^2) | G40: =IF(D40=0,"",E40/D40) | H40: =IF(D40<=1,"",SQRT((F40-(E40^2)/D40)/(D40-1)))
...
